Workbook

Sheet Read me
B1: Allowable total error sources — clinical chemistry and immunochemistry (cobas pro)
B3: What is already filled in
B4: All 63 analytes and 133 control levels from 1 May 2025 – 30 June 2026. The 10 manuscript-panel analytes come first, then the supplementary analytes. On the 'Sigma' sheet, CV, target and analyser offset (bias) are measured values: CV = pooled within-lot CV of the worst analyser; target = mean of the control lot in use at the end of the period; bias = largest analyser offset from that mean. These are the values the rule-design tool uses.
B5: Turkey MoH 2026 percentage limits are filled in for the analytes listed in its Table 1 (comparison source only).
B7: What you fill in
B8: 1. 'TEa input': the YELLOW cells — percentage limits for Labquality, CLIA, Rili-BÄK, Noklus, RCPA, China WS/T 403, SEKK, Belgium, Ricos and any other source, and CVI / CVG from the EFLM Biological Variation Database. The EFLM optimal, desirable and minimum tiers are calculated.
B9: 2. Absolute limits ('ref.' columns) are for reference only. They are defined around the EQA or proficiency-testing sample's target value and are not converted at the IQC concentration; only the % limit is used.
B10: 3. 'References': version, full citation and access date of each source.
B11: 4. 'For the tool': one TEa % per analyte and source, to enter in the tool's 'Allowable error sources' row.
B13: Source priority
B14: Biological variation (EFLM; Ricos as the older compilation) is the primary basis. Labquality, CLIA, Rili-BÄK, Noklus, RCPA, China WS/T 403-2024, SEKK Dmax, Belgium WIV-ISP and Turkey MoH 2026 are comparison sources: none binds this laboratory; they show how far the attainable sigma depends on the specification chosen.
B16: Colours
... B26: PTH: in routine use from September 2025. Vitamin B12 (total) to 19 March 2026, Active B12 from 21 February 2026. Rheumatoid factor not run after 15 June 2026. C-peptide L2: lot 301804 excluded after review (mixed control levels); the 2026 lot is used. Bilirubin and CRP L3: third control (Bili Ped, CRP L3).

Sheet TEa input
A1: TEa input — fill the yellow cells
A2: Percentage limits as numbers (10 = 10%). 'ref.' columns are recorded for reference only and are not used. A source left empty is ignored.
A4: Analyte | B4: Group | C4: Section | D4: Unit | E4: Labquality | G4: CLIA | I4: Rili-BÄK | K4: Noklus | M4: RCPA | O4: China WS/T 403-2024 | Q4: SEKK Dmax | R4: Belgium WIV-ISP | T4: Turkey MoH 2026 | W4: EFLM biological variation | AB4: Ricos (BV) | AE4: Other | AH4: Note
E5: % | F5: Absolute (ref.) | G5: % | H5: Absolute (ref.) | I5: % | J5: Absolute (ref.) | K5: % | L5: Absolute (ref.) | M5: % | N5: Absolute (ref.) | O5: % | P5: Absolute (ref.) | Q5: % | R5: % | S5: Goal type (ref.) | T5: DKD % | U5: DKD absolute as printed (ref.) | V5: IKK max CV % (ref.) | W5: CVI % | X5: CVG % | Y5: Optimal % | Z5: Desirable % | AA5: Minimum % | AB5: Optimal % | AC5: Desirable % | AD5: Minimum % | AE5: Source name | AF5: % | AG5: Absolute (ref.)
A6: Sodium | B6: Panel | C6: Clinical chemistry | D6: mmol/L | E6: 2 | H6: ±4 mmol/L (absolute only) | I6: 3 | J6: EQA col. 5: ±5% | M6: 2 | N6: ±3 mmol/L ≤150 mmol/L | O6: 4 | Q6: 5 | R6: 3.4 | S6: State of the art | T6: 9 | V6: 4 | W6: 0.5 | X6: 0.7 | Y6: =IF(OR(W6="",X6=""),"",1.65*0.25*W6+0.125*SQRT(W6^2+X6^2)) -> 0.31377907 | Z6: =IF(OR(W6="",X6=""),"",1.65*0.5*W6+0.25*SQRT(W6^2+X6^2)) -> 0.62755813 | AA6: =IF(OR(W6="",X6=""),"",1.65*0.75*W6+0.375*SQRT(W6^2+X6^2)) -> 0.9413372 | AC6: 0.73 | AH6: EFLM 95% CI: CVI 0.0–4.3, CVG 0.4–9.7; RCPA: L1 (137) at or below the RCPA cut-off, where RCPA uses an absolute limit; the % is stricter there
A7: Creatinine | B7: Panel | C7: Clinical chemistry | D7: µmol/L | E7: 8 | G7: 10 | H7: ±0.2 mg/dL (greater) | I7: 11.5 | J7: EQA col. 5: ±20% | M7: 8 | N7: ±8 µmol/L ≤100 µmol/L | O7: 12 | P7: ±6 µmol/L at the low end; threshold misprinted in source ("≤5 µmol/L … >4 mmol/L") | Q7: 15 | R7: 10.9 | S7: State of the art | T7: 20 | U7: ± 0.4 mg/dL | V7: 5 | W7: 4.4 | X7: 16.1 | Y7: =IF(OR(W7="",X7=""),"",1.65*0.25*W7+0.125*SQRT(W7^2+X7^2)) -> 3.9013021 | Z7: =IF(OR(W7="",X7=""),"",1.65*0.5*W7+0.25*SQRT(W7^2+X7^2)) -> 7.8026041 | AA7: =IF(OR(W7="",X7=""),"",1.65*0.75*W7+0.375*SQRT(W7^2+X7^2)) -> 11.703906 | AC7: 8.87 | AH7: RCPA: L1 (99.1) at or below the RCPA cut-off, where RCPA uses an absolute limit; the % is stricter there
A8: ALT | B8: Panel | C8: Clinical chemistry | D8: U/L | E8: 12 | G8: 15 | H8: ±6 U/L (greater) | I8: 11.5 | J8: EQA col. 5: ±21% | M8: 12 | N8: ±5 U/L ≤40 U/L | O8: 15 | P8: ±6 U/L (≤40 U/L) | Q8: 15 | R8: 13.3 | S8: State of the art | T8: 20 | U8: ± 6 U/L | V8: 6 | W8: 12.4 | X8: 29.8 | Y8: =IF(OR(W8="",X8=""),"",1.65*0.25*W8+0.125*SQRT(W8^2+X8^2)) -> 9.1496158 | Z8: =IF(OR(W8="",X8=""),"",1.65*0.5*W8+0.25*SQRT(W8^2+X8^2)) -> 18.299232 | AA8: =IF(OR(W8="",X8=""),"",1.65*0.75*W8+0.375*SQRT(W8^2+X8^2)) -> 27.448848 | AC8: 27.48
A9: Glucose | B9: Panel | C9: Clinical chemistry | D9: mmol/L | E9: 6 | G9: 8 | H9: ±6 mg/dL (greater) | I9: 5 | J9: EQA col. 5: ±8% | M9: 8 | N9: ±0.4 mmol/L ≤5.0 mmol/L | O9: 7 | P9: ±0.21 mmol/L (≤3 mmol/L) | Q9: 9 | R9: 6.3 | S9: State of the art | T9: 10 | U9: ± 6 mg/dL | V9: 5 | W9: 4.9 | X9: 8.1 | Y9: =IF(OR(W9="",X9=""),"",1.65*0.25*W9+0.125*SQRT(W9^2+X9^2)) -> 3.204598 | Z9: =IF(OR(W9="",X9=""),"",1.65*0.5*W9+0.25*SQRT(W9^2+X9^2)) -> 6.409196 | AA9: =IF(OR(W9="",X9=""),"",1.65*0.75*W9+0.375*SQRT(W9^2+X9^2)) -> 9.613794 | AC9: 6.96
A10: Calcium | B10: Panel | C10: Clinical chemistry | D10: mmol/L | E10: 3 | H10: ±1.0 mg/dL (absolute only) | I10: 6 | J10: EQA col. 5: ±10% | M10: 4 | N10: ±0.10 mmol/L ≤2.50 mmol/L | O10: 5 | P10: ±0.1 mmol/L (≤2 mmol/L) | Q10: 10 | R10: 5 | S10: State of the art | T10: 10 | U10: ± 1.0 mg/dL | V10: 5 | W10: 1.8 | X10: 2.7 | Y10: =IF(OR(W10="",X10=""),"",1.65*0.25*W10+0.125*SQRT(W10^2+X10^2)) -> 1.1481245 | Z10: =IF(OR(W10="",X10=""),"",1.65*0.5*W10+0.25*SQRT(W10^2+X10^2)) -> 2.296249 | AA10: =IF(OR(W10="",X10=""),"",1.65*0.75*W10+0.375*SQRT(W10^2+X10^2)) -> 3.4443736 | AC10: 2.55 | AH10: RCPA: L1 (2.24) at or below the RCPA cut-off, where RCPA uses an absolute limit; the % is stricter there
A11: TSH | B11: Panel | C11: Immunochemistry | D11: mIU/L | G11: 20 | H11: ±0.2 mIU/L (greater) | I11: 13.5 | J11: EQA col. 5: ±24% | M11: 20 | N11: ±0.1 mU/L ≤0.5 mU/L | O11: 20 | P11: ±0.1 mIU/L (≤0.5 mIU/L) | Q11: 14 | T11: 25 | U11: ± 0.2 mIU/L | V11: 10 | W11: 17.9 | X11: 36.1 | Y11: =IF(OR(W11="",X11=""),"",1.65*0.25*W11+0.125*SQRT(W11^2+X11^2)) -> 12.420521 | Z11: =IF(OR(W11="",X11=""),"",1.65*0.5*W11+0.25*SQRT(W11^2+X11^2)) -> 24.841042 | AA11: =IF(OR(W11="",X11=""),"",1.65*0.75*W11+0.375*SQRT(W11^2+X11^2)) -> 37.261563 | AC11: 23.7
A12: hs-Troponin T | B12: Panel | C12: Immunochemistry | D12: ng/L | G12: 30 | H12: ±0.2 ng/mL = 200 ng/L (greater) | I12: 20 | J12: EQA col. 5: ±33% | K12: 15 | M12: 20 | N12: ±10 ng/L ≤50 ng/L | W12: 11.4 | X12: 30.9 | Y12: =IF(OR(W12="",X12=""),"",1.65*0.25*W12+0.125*SQRT(W12^2+X12^2)) -> 8.8194808 | Z12: =IF(OR(W12="",X12=""),"",1.65*0.5*W12+0.25*SQRT(W12^2+X12^2)) -> 17.638962 | AA12: =IF(OR(W12="",X12=""),"",1.65*0.75*W12+0.375*SQRT(W12^2+X12^2)) -> 26.458443 | AH12: RCPA: L1 (18.8) at or below the RCPA cut-off, where RCPA uses an absolute limit; the % is stricter there
A13: Ferritin | B13: Panel | C13: Immunochemistry | D13: µg/L | E13: 12 | G13: 20 | I13: 13.5 | J13: EQA col. 5: ±25% | M13: 15 | N13: ±4 µg/L ≤27 µg/L | O13: 25 | P13: ±6 µg/L (≤24 µg/L) | Q13: 24 | T13: 25 | U13: ± 5 µg/L | V13: 10 | W13: 12.9 | Y13: =IF(OR(W13="",X13=""),"",1.65*0.25*W13+0.125*SQRT(W13^2+X13^2)) | Z13: =IF(OR(W13="",X13=""),"",1.65*0.5*W13+0.25*SQRT(W13^2+X13^2)) | AA13: =IF(OR(W13="",X13=""),"",1.65*0.75*W13+0.375*SQRT(W13^2+X13^2)) | AC13: 16.9 | AH13: EFLM: CVI 12.9%, CVG not available — BV TEa not computed
A14: PSA | B14: Panel | C14: Immunochemistry | D14: µg/L | G14: 20 | H14: ±0.2 ng/mL (greater) | I14: 15.5 | J14: EQA col. 5: ±25% | M14: 8 | N14: ±0.4 µg/L ≤5.0 µg/L | O14: 25 | P14: ±0.75 µg/L (≤3 µg/L) | Q14: 15 | T14: 25 | U14: ± 0.2 µg/L | V14: 10 | W14: 6.8 | X14: 42 | Y14: =IF(OR(W14="",X14=""),"",1.65*0.25*W14+0.125*SQRT(W14^2+X14^2)) -> 8.1233644 | Z14: =IF(OR(W14="",X14=""),"",1.65*0.5*W14+0.25*SQRT(W14^2+X14^2)) -> 16.246729 | AA14: =IF(OR(W14="",X14=""),"",1.65*0.75*W14+0.375*SQRT(W14^2+X14^2)) -> 24.370093 | AC14: 33.6 | AH14: RCPA: L1 (4.05) at or below the RCPA cut-off, where RCPA uses an absolute limit; the % is stricter there
A15: 25-OH vitamin D | B15: Panel | C15: Immunochemistry | D15: nmol/L | I15: 25 | J15: no EQA limit (col. 5) | M15: 15 | N15: ±9 nmol/L ≤60 nmol/L | T15: 25 | U15: ± 5.0 µg/L | V15: 10 | W15: 6.8 | X15: 37.6 | Y15: =IF(OR(W15="",X15=""),"",1.65*0.25*W15+0.125*SQRT(W15^2+X15^2)) -> 7.5812433 | Z15: =IF(OR(W15="",X15=""),"",1.65*0.5*W15+0.25*SQRT(W15^2+X15^2)) -> 15.162487 | AA15: =IF(OR(W15="",X15=""),"",1.65*0.75*W15+0.375*SQRT(W15^2+X15^2)) -> 22.74373 | AE15: RfB | AF15: 30
A16: Potassium | B16: Supplementary | C16: Clinical chemistry | D16: mmol/L | E16: 4 | H16: ±0.3 mmol/L (absolute only) | I16: 4.5 | J16: EQA col. 5: ±8% | M16: 5 | N16: ±0.2 mmol/L ≤4.0 mmol/L | O16: 6 | P16: ±0.2 mmol/L (≤3.3 mmol/L) | Q16: 8 | R16: 4.8 | S16: Biological variability | T16: 9 | U16: ± 0.3 mmol/L | V16: 4 | Y16: =IF(OR(W16="",X16=""),"",1.65*0.25*W16+0.125*SQRT(W16^2+X16^2)) | Z16: =IF(OR(W16="",X16=""),"",1.65*0.5*W16+0.25*SQRT(W16^2+X16^2)) | AA16: =IF(OR(W16="",X16=""),"",1.65*0.75*W16+0.375*SQRT(W16^2+X16^2)) | AC16: 5.61 | AH16: RCPA: L1 (3.98) at or below the RCPA cut-off, where RCPA uses an absolute limit; the % is stricter there
A17: Chloride | B17: Supplementary | C17: Clinical chemistry | D17: mmol/L | E17: 3 | G17: 5 | I17: 4.5 | J17: EQA col. 5: ±8% | M17: 3 | N17: ±3 mmol/L ≤100 mmol/L | O17: 4 | Q17: 7 | R17: 5.1 | S17: State of the art | Y17: =IF(OR(W17="",X17=""),"",1.65*0.25*W17+0.125*SQRT(W17^2+X17^2)) | Z17: =IF(OR(W17="",X17=""),"",1.65*0.5*W17+0.25*SQRT(W17^2+X17^2)) | AA17: =IF(OR(W17="",X17=""),"",1.65*0.75*W17+0.375*SQRT(W17^2+X17^2)) | AC17: 1.5 | AH17: RCPA: L1 (97.6) at or below the RCPA cut-off, where RCPA uses an absolute limit; the % is stricter there
A18: Urea | B18: Supplementary | C18: Clinical chemistry | D18: mmol/L | E18: 10 | G18: 9 | H18: ±2 mg/dL urea N (greater) | I18: 10.5 | J18: EQA col. 5: ±20% | M18: 12 | N18: ±0.5 mmol/L ≤4.0 mmol/L | O18: 8 | P18: ±0.32 mmol/L (≤4 mmol/L) | Q18: 15 | R18: 9 | S18: Biological variability | T18: 20 | U18: ± 4.3 mg/dL (urea) | V18: 5 | Y18: =IF(OR(W18="",X18=""),"",1.65*0.25*W18+0.125*SQRT(W18^2+X18^2)) | Z18: =IF(OR(W18="",X18=""),"",1.65*0.5*W18+0.25*SQRT(W18^2+X18^2)) | AA18: =IF(OR(W18="",X18=""),"",1.65*0.75*W18+0.375*SQRT(W18^2+X18^2)) | AC18: 15.55
A19: Urate | B19: Supplementary | C19: Clinical chemistry | D19: µmol/L | E19: 8 | G19: 10 | I19: 7 | J19: EQA col. 5: ±13% | M19: 8 | N19: ±0.030 mmol/L ≤0.380 mmol/L | O19: 12 | Q19: 14 | R19: 8 | S19: State of the art | T19: 13 | U19: ± 0.5 mg/dL | V19: 5 | Y19: =IF(OR(W19="",X19=""),"",1.65*0.25*W19+0.125*SQRT(W19^2+X19^2)) | Z19: =IF(OR(W19="",X19=""),"",1.65*0.5*W19+0.25*SQRT(W19^2+X19^2)) | AA19: =IF(OR(W19="",X19=""),"",1.65*0.75*W19+0.375*SQRT(W19^2+X19^2)) | AC19: 11.97 | AH19: RCPA: L1 (289) at or below the RCPA cut-off, where RCPA uses an absolute limit; the % is stricter there
A20: AST | B20: Supplementary | C20: Clinical chemistry | D20: U/L | E20: 12 | G20: 15 | H20: ±6 U/L (greater) | I20: 11.5 | J20: EQA col. 5: ±21% | M20: 12 | N20: ±5 U/L ≤40 U/L | O20: 15 | P20: ±6 U/L (≤40 U/L) | Q20: 15 | R20: 11.3 | S20: Biological variability | T20: 20 | U20: ± 6 U/L | V20: 6 | Y20: =IF(OR(W20="",X20=""),"",1.65*0.25*W20+0.125*SQRT(W20^2+X20^2)) | Z20: =IF(OR(W20="",X20=""),"",1.65*0.5*W20+0.25*SQRT(W20^2+X20^2)) | AA20: =IF(OR(W20="",X20=""),"",1.65*0.75*W20+0.375*SQRT(W20^2+X20^2)) | AC20: 16.69
A21: ALP | B21: Supplementary | C21: Clinical chemistry | D21: U/L | E21: 12 | G21: 20 | I21: 11 | J21: EQA col. 5: ±18% | M21: 12 | N21: ±15 U/L ≤125 U/L | O21: 18 | P21: ±9 U/L (≤60 U/L) | Q21: 24 | T21: 30 | V21: 8 | Y21: =IF(OR(W21="",X21=""),"",1.65*0.25*W21+0.125*SQRT(W21^2+X21^2)) | Z21: =IF(OR(W21="",X21=""),"",1.65*0.5*W21+0.25*SQRT(W21^2+X21^2)) | AA21: =IF(OR(W21="",X21=""),"",1.65*0.75*W21+0.375*SQRT(W21^2+X21^2)) | AC21: 12.04 | AH21: RCPA: L1 (90) at or below the RCPA cut-off, where RCPA uses an absolute limit; the % is stricter there
A22: GGT | B22: Supplementary | C22: Clinical chemistry | D22: U/L | E22: 12 | G22: 15 | H22: ±5 U/L (greater) | I22: 11.5 | J22: EQA col. 5: ±21% | M22: 12 | N22: ±5 U/L ≤40 U/L | O22: 11 | P22: ±4.4 U/L (≤40 U/L) | Q22: 15 | R22: 14.2 | S22: State of the art | T22: 20 | U22: ± 5 U/L | V22: 6 | Y22: =IF(OR(W22="",X22=""),"",1.65*0.25*W22+0.125*SQRT(W22^2+X22^2)) | Z22: =IF(OR(W22="",X22=""),"",1.65*0.5*W22+0.25*SQRT(W22^2+X22^2)) | AA22: =IF(OR(W22="",X22=""),"",1.65*0.75*W22+0.375*SQRT(W22^2+X22^2)) | AC22: 22.11
A23: LD | B23: Supplementary | C23: Clinical chemistry | D23: U/L | E23: 12 | G23: 15 | I23: 9 | J23: EQA col. 5: ±18% | M23: 8 | N23: ±20 U/L ≤250 U/L | O23: 11 | Q23: 21 | R23: 10.7 | S23: State of the art | Y23: =IF(OR(W23="",X23=""),"",1.65*0.25*W23+0.125*SQRT(W23^2+X23^2)) | Z23: =IF(OR(W23="",X23=""),"",1.65*0.5*W23+0.25*SQRT(W23^2+X23^2)) | AA23: =IF(OR(W23="",X23=""),"",1.65*0.75*W23+0.375*SQRT(W23^2+X23^2)) | AC23: 11.4 | AH23: RCPA: L1 (187) at or below the RCPA cut-off, where RCPA uses an absolute limit; the % is stricter there
A24: CK | B24: Supplementary | C24: Clinical chemistry | D24: U/L | E24: 12 | G24: 20 | I24: 11 | J24: EQA col. 5: ±20% | M24: 12 | N24: ±15 U/L ≤125 U/L | O24: 15 | Q24: 21 | T24: 20 | V24: 10 | Y24: =IF(OR(W24="",X24=""),"",1.65*0.25*W24+0.125*SQRT(W24^2+X24^2)) | Z24: =IF(OR(W24="",X24=""),"",1.65*0.5*W24+0.25*SQRT(W24^2+X24^2)) | AA24: =IF(OR(W24="",X24=""),"",1.65*0.75*W24+0.375*SQRT(W24^2+X24^2)) | AC24: 30.3 | AH24: RCPA: L1 (101) at or below the RCPA cut-off, where RCPA uses an absolute limit; the % is stricter there
A25: Amylase | B25: Supplementary | C25: Clinical chemistry | D25: U/L | E25: 12 | G25: 20 | I25: 7 | J25: no EQA limit (col. 5) | M25: 10 | N25: ±10 U/L ≤100 U/L | O25: 15 | P25: ±9 U/L (≤50 U/L) | Q25: 15 | Y25: =IF(OR(W25="",X25=""),"",1.65*0.25*W25+0.125*SQRT(W25^2+X25^2)) | Z25: =IF(OR(W25="",X25=""),"",1.65*0.5*W25+0.25*SQRT(W25^2+X25^2)) | AA25: =IF(OR(W25="",X25=""),"",1.65*0.75*W25+0.375*SQRT(W25^2+X25^2)) | AC25: 14.6
A26: Lipase | B26: Supplementary | C26: Clinical chemistry | D26: U/L | E26: 12 | I26: 11 | J26: no EQA limit (col. 5) | M26: 20 | N26: ±12 U/L ≤60 U/L | Q26: 24 | R26: 14.3 | S26: State of the art | Y26: =IF(OR(W26="",X26=""),"",1.65*0.25*W26+0.125*SQRT(W26^2+X26^2)) | Z26: =IF(OR(W26="",X26=""),"",1.65*0.5*W26+0.25*SQRT(W26^2+X26^2)) | AA26: =IF(OR(W26="",X26=""),"",1.65*0.75*W26+0.375*SQRT(W26^2+X26^2)) | AC26: 37.88 | AH26: RCPA: L1 (52.6) at or below the RCPA cut-off, where RCPA uses an absolute limit; the % is stricter there
A27: Bilirubin | B27: Supplementary | C27: Clinical chemistry | D27: µmol/L | E27: 12 | G27: 20 | H27: ±0.4 mg/dL (greater) | I27: 13 | J27: EQA col. 5: ±22% | M27: 12 | N27: ±3 µmol/L ≤25 µmol/L | O27: 15 | P27: ±12.4 µmol/L (≤16 µmol/L) | Q27: 21 | R27: 12 | S27: State of the art | T27: 20 | U27: ± 0.4 mg/dL | V27: 8 | Y27: =IF(OR(W27="",X27=""),"",1.65*0.25*W27+0.125*SQRT(W27^2+X27^2)) | Z27: =IF(OR(W27="",X27=""),"",1.65*0.5*W27+0.25*SQRT(W27^2+X27^2)) | AA27: =IF(OR(W27="",X27=""),"",1.65*0.75*W27+0.375*SQRT(W27^2+X27^2)) | AC27: 26.94 | AH27: RCPA: L1 (17) at or below the RCPA cut-off, where RCPA uses an absolute limit; the % is stricter there; Rili-BÄK col. 3: 13% applies >34 µmol/L (L2, L3); 22% at ≤34 µmol/L (L1 ≈ 17)
A28: Albumin | B28: Supplementary | C28: Clinical chemistry | D28: g/L | E28: 5 | G28: 8 | I28: 12.5 | J28: EQA col. 5: ±20% | M28: 6 | N28: ±2 g/L ≤33 g/L | O28: 6 | Q28: 12 | R28: 10.7 | S28: State of the art | T28: 15 | V28: 6 | Y28: =IF(OR(W28="",X28=""),"",1.65*0.25*W28+0.125*SQRT(W28^2+X28^2)) | Z28: =IF(OR(W28="",X28=""),"",1.65*0.5*W28+0.25*SQRT(W28^2+X28^2)) | AA28: =IF(OR(W28="",X28=""),"",1.65*0.75*W28+0.375*SQRT(W28^2+X28^2)) | AC28: 4.07 | AH28: RCPA: L1 (31.5) at or below the RCPA cut-off, where RCPA uses an absolute limit; the % is stricter there
A29: Total protein | B29: Supplementary | C29: Clinical chemistry | D29: g/L | E29: 5 | G29: 8 | I29: 6 | J29: EQA col. 5: ±10% | M29: 5 | N29: ±3 g/L ≤60 g/L | O29: 5 | Q29: 9 | R29: 6.8 | S29: State of the art | T29: 10 | V29: 5 | Y29: =IF(OR(W29="",X29=""),"",1.65*0.25*W29+0.125*SQRT(W29^2+X29^2)) | Z29: =IF(OR(W29="",X29=""),"",1.65*0.5*W29+0.25*SQRT(W29^2+X29^2)) | AA29: =IF(OR(W29="",X29=""),"",1.65*0.75*W29+0.375*SQRT(W29^2+X29^2)) | AC29: 3.63 | AH29: RCPA: L1 (51.7) at or below the RCPA cut-off, where RCPA uses an absolute limit; the % is stricter there
A30: Phosphate | B30: Supplementary | C30: Clinical chemistry | D30: mmol/L | E30: 6 | G30: 10 | H30: ±0.3 mg/dL (greater) | I30: 9 | J30: EQA col. 5: ±16% | M30: 8 | N30: ±0.06 mmol/L ≤0.75 mmol/L | O30: 10 | Q30: 15 | R30: 7.4 | S30: Biological variability | T30: 16 | U30: ± 0.3 mg/dL | V30: 8 | Y30: =IF(OR(W30="",X30=""),"",1.65*0.25*W30+0.125*SQRT(W30^2+X30^2)) | Z30: =IF(OR(W30="",X30=""),"",1.65*0.5*W30+0.25*SQRT(W30^2+X30^2)) | AA30: =IF(OR(W30="",X30=""),"",1.65*0.75*W30+0.375*SQRT(W30^2+X30^2)) | AC30: 10.11
A31: Magnesium | B31: Supplementary | C31: Clinical chemistry | D31: mmol/L | E31: 6 | G31: 15 | I31: 7.5 | J31: EQA col. 5: ±15% | M31: 8 | N31: ±0.10 mmol/L ≤1.25 mmol/L | O31: 15 | P31: ±0.12 mmol/L (≤0.8 mmol/L) | Q31: 15 | R31: 8.9 | S31: State of the art | T31: 15 | V31: 8 | Y31: =IF(OR(W31="",X31=""),"",1.65*0.25*W31+0.125*SQRT(W31^2+X31^2)) | Z31: =IF(OR(W31="",X31=""),"",1.65*0.5*W31+0.25*SQRT(W31^2+X31^2)) | AA31: =IF(OR(W31="",X31=""),"",1.65*0.75*W31+0.375*SQRT(W31^2+X31^2)) | AC31: 4.8 | AH31: RCPA: L1 (0.797) at or below the RCPA cut-off, where RCPA uses an absolute limit; the % is stricter there; China: L1 (0.797) at or below the cut-off (absolute limit there; % stricter)
A32: CRP | B32: Supplementary | C32: Clinical chemistry | D32: mg/L | G32: 30 | H32: ±1 mg/L (greater); hs-CRP | I32: 13.5 | J32: EQA col. 5: ±20% | M32: 20 | N32: ±0.8 mg/L ≤4.0 mg/L | T32: 20 | V32: 8 | Y32: =IF(OR(W32="",X32=""),"",1.65*0.25*W32+0.125*SQRT(W32^2+X32^2)) | Z32: =IF(OR(W32="",X32=""),"",1.65*0.5*W32+0.25*SQRT(W32^2+X32^2)) | AA32: =IF(OR(W32="",X32=""),"",1.65*0.75*W32+0.375*SQRT(W32^2+X32^2))
A33: Cholesterol | B33: Supplementary | C33: Clinical chemistry | D33: mmol/L | E33: 5 | G33: 10 | I33: 7 | J33: EQA col. 5: ±13% | M33: 6 | N33: ±0.30 mmol/L ≤5.00 mmol/L | O33: 9 | Q33: 8.5 | R33: 6.5 | S33: Biological variability | T33: 13 | V33: 5 | Y33: =IF(OR(W33="",X33=""),"",1.65*0.25*W33+0.125*SQRT(W33^2+X33^2)) | Z33: =IF(OR(W33="",X33=""),"",1.65*0.5*W33+0.25*SQRT(W33^2+X33^2)) | AA33: =IF(OR(W33="",X33=""),"",1.65*0.75*W33+0.375*SQRT(W33^2+X33^2)) | AC33: 9.01 | AH33: RCPA: L1 (3.35) at or below the RCPA cut-off, where RCPA uses an absolute limit; the % is stricter there
A34: HDL cholesterol | B34: Supplementary | C34: Clinical chemistry | D34: mmol/L | E34: 10 | G34: 20 | H34: ±6 mg/dL (greater) | I34: 13 | J34: no EQA limit (col. 5) | M34: 12 | N34: ±0.10 mmol/L ≤0.80 mmol/L | O34: 20 | P34: ±0.16 mmol/L (≤0.8 mmol/L) | Q34: 15 | R34: 15.3 | S34: State of the art | T34: 20 | U34: ± 6 mg/dL | V34: 8 | Y34: =IF(OR(W34="",X34=""),"",1.65*0.25*W34+0.125*SQRT(W34^2+X34^2)) | Z34: =IF(OR(W34="",X34=""),"",1.65*0.5*W34+0.25*SQRT(W34^2+X34^2)) | AA34: =IF(OR(W34="",X34=""),"",1.65*0.75*W34+0.375*SQRT(W34^2+X34^2)) | AC34: 11.63
A35: LDL cholesterol | B35: Supplementary | C35: Clinical chemistry | D35: mmol/L | E35: 10 | G35: 20 | H35: (direct) | I35: 9 | J35: no EQA limit (col. 5) | M35: 10 | N35: ±0.20 mmol/L ≤2.00 mmol/L | O35: 20 | P35: ±0.4 mmol/L (≤2 mmol/L) | T35: 20 | V35: 8 | Y35: =IF(OR(W35="",X35=""),"",1.65*0.25*W35+0.125*SQRT(W35^2+X35^2)) | Z35: =IF(OR(W35="",X35=""),"",1.65*0.5*W35+0.25*SQRT(W35^2+X35^2)) | AA35: =IF(OR(W35="",X35=""),"",1.65*0.75*W35+0.375*SQRT(W35^2+X35^2)) | AH35: RCPA: L1 (1.85) at or below the RCPA cut-off, where RCPA uses an absolute limit; the % is stricter there; China: L1 (1.85) at or below the cut-off (absolute limit there; % stricter)
A36: Triglycerides | B36: Supplementary | C36: Clinical chemistry | D36: mmol/L | E36: 15 | G36: 15 | I36: 9 | J36: EQA col. 5: ±16% | M36: 12 | N36: ±0.20 mmol/L ≤1.60 mmol/L | O36: 14 | Q36: 15 | R36: 20 | S36: State of the art | T36: 15 | V36: 6 | Y36: =IF(OR(W36="",X36=""),"",1.65*0.25*W36+0.125*SQRT(W36^2+X36^2)) | Z36: =IF(OR(W36="",X36=""),"",1.65*0.5*W36+0.25*SQRT(W36^2+X36^2)) | AA36: =IF(OR(W36="",X36=""),"",1.65*0.75*W36+0.375*SQRT(W36^2+X36^2)) | AC36: 25.99 | AH36: RCPA: L1 (0.939) at or below the RCPA cut-off, where RCPA uses an absolute limit; the % is stricter there
A37: Iron | B37: Supplementary | C37: Clinical chemistry | D37: µmol/L | E37: 12 | G37: 15 | M37: 12 | N37: ±3 µmol/L ≤25 µmol/L | O37: 15 | P37: ±2.1 µmol/L (≤14 µmol/L) | Q37: 15 | R37: 8.3 | S37: State of the art | Y37: =IF(OR(W37="",X37=""),"",1.65*0.25*W37+0.125*SQRT(W37^2+X37^2)) | Z37: =IF(OR(W37="",X37=""),"",1.65*0.5*W37+0.25*SQRT(W37^2+X37^2)) | AA37: =IF(OR(W37="",X37=""),"",1.65*0.75*W37+0.375*SQRT(W37^2+X37^2)) | AC37: 30.7 | AH37: RCPA: L1 (13.4) at or below the RCPA cut-off, where RCPA uses an absolute limit; the % is stricter there; China: L1 (13.4) at or below the cut-off (absolute limit there; % stricter)
A38: Transferrin | B38: Supplementary | C38: Clinical chemistry | D38: g/L | E38: 8 | I38: 8 | J38: EQA col. 5: ±12% | M38: 8 | N38: ±0.20 g/L ≤2.50 g/L | Y38: =IF(OR(W38="",X38=""),"",1.65*0.25*W38+0.125*SQRT(W38^2+X38^2)) | Z38: =IF(OR(W38="",X38=""),"",1.65*0.5*W38+0.25*SQRT(W38^2+X38^2)) | AA38: =IF(OR(W38="",X38=""),"",1.65*0.75*W38+0.375*SQRT(W38^2+X38^2)) | AH38: RCPA: L1 (2.13) at or below the RCPA cut-off, where RCPA uses an absolute limit; the % is stricter there
A39: IgA | B39: Supplementary | C39: Clinical chemistry | D39: g/L | E39: 15 | G39: 20 | I39: 12 | J39: EQA col. 5: ±20% | O39: 20 | Q39: 20 | R39: 10.6 | S39: State of the art | Y39: =IF(OR(W39="",X39=""),"",1.65*0.25*W39+0.125*SQRT(W39^2+X39^2)) | Z39: =IF(OR(W39="",X39=""),"",1.65*0.5*W39+0.25*SQRT(W39^2+X39^2)) | AA39: =IF(OR(W39="",X39=""),"",1.65*0.75*W39+0.375*SQRT(W39^2+X39^2)) | AC39: 13.5
A40: IgG | B40: Supplementary | C40: Clinical chemistry | D40: g/L | E40: 8 | G40: 20 | I40: 10 | J40: EQA col. 5: ±18% | O40: 20 | Q40: 18 | R40: 9.3 | S40: State of the art | Y40: =IF(OR(W40="",X40=""),"",1.65*0.25*W40+0.125*SQRT(W40^2+X40^2)) | Z40: =IF(OR(W40="",X40=""),"",1.65*0.5*W40+0.25*SQRT(W40^2+X40^2)) | AA40: =IF(OR(W40="",X40=""),"",1.65*0.75*W40+0.375*SQRT(W40^2+X40^2)) | AC40: 8
A41: IgM | B41: Supplementary | C41: Clinical chemistry | D41: g/L | E41: 15 | G41: 20 | I41: 13 | J41: EQA col. 5: ±26% | O41: 25 | Q41: 21 | R41: 12.2 | S41: State of the art | Y41: =IF(OR(W41="",X41=""),"",1.65*0.25*W41+0.125*SQRT(W41^2+X41^2)) | Z41: =IF(OR(W41="",X41=""),"",1.65*0.5*W41+0.25*SQRT(W41^2+X41^2)) | AA41: =IF(OR(W41="",X41=""),"",1.65*0.75*W41+0.375*SQRT(W41^2+X41^2)) | AC41: 16.8
...

Sheet Sigma
A1: Effective TEa and sigma — per control level
A2: CV, target and bias are measured (1 May 2025 – 30 June 2026). Effective TEa = the % limit of each source. Sigma = (TEa − |bias|) / CV.
A4: Analyte | B4: Level | C4: Control | D4: Target (current lot mean) | E4: CV % (worst analyser) | F4: Bias % (largest analyser offset) | G4: n | H4: Worst analyser | I4: Row | J4: Effective TEa % | AA4: Sigma
J5: Labquality | K5: CLIA | L5: Rili-BÄK | M5: Noklus | N5: RCPA | O5: China WS/T 403-2024 | P5: SEKK Dmax | Q5: Belgium WIV-ISP | R5: Turkey MoH 2026 | S5: BV EFLM (optimal) | T5: BV EFLM (desirable) | U5: BV EFLM (minimum) | V5: BV Ricos (optimal) | W5: BV Ricos (desirable) | X5: BV Ricos (minimum) | Y5: Other | AA5: Labquality | AB5: CLIA | AC5: Rili-BÄK | AD5: Noklus | AE5: RCPA | AF5: China WS/T 403-2024 | AG5: SEKK Dmax | AH5: Belgium WIV-ISP | AI5: Turkey MoH 2026 | AJ5: BV EFLM (optimal) | AK5: BV EFLM (desirable) | AL5: BV EFLM (minimum) | AM5: BV Ricos (optimal) | AN5: BV Ricos (desirable) | AO5: BV Ricos (minimum) | AP5: Other
A6: Sodium | B6: L1 | C6: ClinChem 2 | D6: 136.569 | E6: 1.088 | F6: 0.236 | G6: 1777 | H6: NISE-2.2 | I6: =MATCH(A6,'TEa input'!$A$6:$A$68,0) -> 1 | J6: =IF(INDEX('TEa input'!$E$6:$E$68,$I6)="","",INDEX('TEa input'!$E$6:$E$68,$I6)) -> 2 | K6: =IF(INDEX('TEa input'!$G$6:$G$68,$I6)="","",INDEX('TEa input'!$G$6:$G$68,$I6)) | L6: =IF(INDEX('TEa input'!$I$6:$I$68,$I6)="","",INDEX('TEa input'!$I$6:$I$68,$I6)) -> 3 | M6: =IF(INDEX('TEa input'!$K$6:$K$68,$I6)="","",INDEX('TEa input'!$K$6:$K$68,$I6)) | N6: =IF(INDEX('TEa input'!$M$6:$M$68,$I6)="","",INDEX('TEa input'!$M$6:$M$68,$I6)) -> 2 | O6: =IF(INDEX('TEa input'!$O$6:$O$68,$I6)="","",INDEX('TEa input'!$O$6:$O$68,$I6)) -> 4 | P6: =IF(INDEX('TEa input'!$Q$6:$Q$68,$I6)="","",INDEX('TEa input'!$Q$6:$Q$68,$I6)) -> 5 | Q6: =IF(INDEX('TEa input'!$R$6:$R$68,$I6)="","",INDEX('TEa input'!$R$6:$R$68,$I6)) -> 3.4 | R6: =IF(INDEX('TEa input'!$T$6:$T$68,$I6)="","",INDEX('TEa input'!$T$6:$T$68,$I6)) -> 9 | S6: =IF(INDEX('TEa input'!$Y$6:$Y$68,$I6)="","",INDEX('TEa input'!$Y$6:$Y$68,$I6)) -> 0.31377907 | T6: =IF(INDEX('TEa input'!$Z$6:$Z$68,$I6)="","",INDEX('TEa input'!$Z$6:$Z$68,$I6)) -> 0.62755813 | U6: =IF(INDEX('TEa input'!$AA$6:$AA$68,$I6)="","",INDEX('TEa input'!$AA$6:$AA$68,$I6)) -> 0.9413372 | V6: =IF(INDEX('TEa input'!$AB$6:$AB$68,$I6)="","",INDEX('TEa input'!$AB$6:$AB$68,$I6)) | W6: =IF(INDEX('TEa input'!$AC$6:$AC$68,$I6)="","",INDEX('TEa input'!$AC$6:$AC$68,$I6)) -> 0.73 | X6: =IF(INDEX('TEa input'!$AD$6:$AD$68,$I6)="","",INDEX('TEa input'!$AD$6:$AD$68,$I6)) | Y6: =IF(INDEX('TEa input'!$AF$6:$AF$68,$I6)="","",INDEX('TEa input'!$AF$6:$AF$68,$I6)) | AA6: =IF(OR(J6="",$E6="",N($E6)<=0),"",(J6-ABS(N($F6)))/$E6) -> 1.6213235 | AB6: =IF(OR(K6="",$E6="",N($E6)<=0),"",(K6-ABS(N($F6)))/$E6) | AC6: =IF(OR(L6="",$E6="",N($E6)<=0),"",(L6-ABS(N($F6)))/$E6) -> 2.5404412 | AD6: =IF(OR(M6="",$E6="",N($E6)<=0),"",(M6-ABS(N($F6)))/$E6) | AE6: =IF(OR(N6="",$E6="",N($E6)<=0),"",(N6-ABS(N($F6)))/$E6) -> 1.6213235 | AF6: =IF(OR(O6="",$E6="",N($E6)<=0),"",(O6-ABS(N($F6)))/$E6) -> 3.4595588 | AG6: =IF(OR(P6="",$E6="",N($E6)<=0),"",(P6-ABS(N($F6)))/$E6) -> 4.3786765 | AH6: =IF(OR(Q6="",$E6="",N($E6)<=0),"",(Q6-ABS(N($F6)))/$E6) -> 2.9080882 | ... AP6: =IF(OR(Y6="",$E6="",N($E6)<=0),"",(Y6-ABS(N($F6)))/$E6)
A7: Sodium | B7: L2 | C7: ClinChem 3 | D7: 154.677 | E7: 0.726 | F7: 0.251 | G7: 1787 | H7: NISE-2.2 | I7: =MATCH(A7,'TEa input'!$A$6:$A$68,0) -> 1 | J7: =IF(INDEX('TEa input'!$E$6:$E$68,$I7)="","",INDEX('TEa input'!$E$6:$E$68,$I7)) -> 2 | K7: =IF(INDEX('TEa input'!$G$6:$G$68,$I7)="","",INDEX('TEa input'!$G$6:$G$68,$I7)) | L7: =IF(INDEX('TEa input'!$I$6:$I$68,$I7)="","",INDEX('TEa input'!$I$6:$I$68,$I7)) -> 3 | M7: =IF(INDEX('TEa input'!$K$6:$K$68,$I7)="","",INDEX('TEa input'!$K$6:$K$68,$I7)) | N7: =IF(INDEX('TEa input'!$M$6:$M$68,$I7)="","",INDEX('TEa input'!$M$6:$M$68,$I7)) -> 2 | O7: =IF(INDEX('TEa input'!$O$6:$O$68,$I7)="","",INDEX('TEa input'!$O$6:$O$68,$I7)) -> 4 | P7: =IF(INDEX('TEa input'!$Q$6:$Q$68,$I7)="","",INDEX('TEa input'!$Q$6:$Q$68,$I7)) -> 5 | Q7: =IF(INDEX('TEa input'!$R$6:$R$68,$I7)="","",INDEX('TEa input'!$R$6:$R$68,$I7)) -> 3.4 | R7: =IF(INDEX('TEa input'!$T$6:$T$68,$I7)="","",INDEX('TEa input'!$T$6:$T$68,$I7)) -> 9 | S7: =IF(INDEX('TEa input'!$Y$6:$Y$68,$I7)="","",INDEX('TEa input'!$Y$6:$Y$68,$I7)) -> 0.31377907 | T7: =IF(INDEX('TEa input'!$Z$6:$Z$68,$I7)="","",INDEX('TEa input'!$Z$6:$Z$68,$I7)) -> 0.62755813 | U7: =IF(INDEX('TEa input'!$AA$6:$AA$68,$I7)="","",INDEX('TEa input'!$AA$6:$AA$68,$I7)) -> 0.9413372 | V7: =IF(INDEX('TEa input'!$AB$6:$AB$68,$I7)="","",INDEX('TEa input'!$AB$6:$AB$68,$I7)) | W7: =IF(INDEX('TEa input'!$AC$6:$AC$68,$I7)="","",INDEX('TEa input'!$AC$6:$AC$68,$I7)) -> 0.73 | X7: =IF(INDEX('TEa input'!$AD$6:$AD$68,$I7)="","",INDEX('TEa input'!$AD$6:$AD$68,$I7)) | Y7: =IF(INDEX('TEa input'!$AF$6:$AF$68,$I7)="","",INDEX('TEa input'!$AF$6:$AF$68,$I7)) | AA7: =IF(OR(J7="",$E7="",N($E7)<=0),"",(J7-ABS(N($F7)))/$E7) -> 2.4090909 | AB7: =IF(OR(K7="",$E7="",N($E7)<=0),"",(K7-ABS(N($F7)))/$E7) | AC7: =IF(OR(L7="",$E7="",N($E7)<=0),"",(L7-ABS(N($F7)))/$E7) -> 3.7865014 | AD7: =IF(OR(M7="",$E7="",N($E7)<=0),"",(M7-ABS(N($F7)))/$E7) | AE7: =IF(OR(N7="",$E7="",N($E7)<=0),"",(N7-ABS(N($F7)))/$E7) -> 2.4090909 | AF7: =IF(OR(O7="",$E7="",N($E7)<=0),"",(O7-ABS(N($F7)))/$E7) -> 5.1639118 | AG7: =IF(OR(P7="",$E7="",N($E7)<=0),"",(P7-ABS(N($F7)))/$E7) -> 6.5413223 | AH7: =IF(OR(Q7="",$E7="",N($E7)<=0),"",(Q7-ABS(N($F7)))/$E7) -> 4.3374656 | ... AP7: =IF(OR(Y7="",$E7="",N($E7)<=0),"",(Y7-ABS(N($F7)))/$E7)
A8: Creatinine | B8: L1 | C8: ClinChem 2 | D8: 99.1432 | E8: 1.903 | F8: 0.116 | G8: 1325 | H8: c703-1.1 | I8: =MATCH(A8,'TEa input'!$A$6:$A$68,0) -> 2 | J8: =IF(INDEX('TEa input'!$E$6:$E$68,$I8)="","",INDEX('TEa input'!$E$6:$E$68,$I8)) -> 8 | K8: =IF(INDEX('TEa input'!$G$6:$G$68,$I8)="","",INDEX('TEa input'!$G$6:$G$68,$I8)) -> 10 | L8: =IF(INDEX('TEa input'!$I$6:$I$68,$I8)="","",INDEX('TEa input'!$I$6:$I$68,$I8)) -> 11.5 | M8: =IF(INDEX('TEa input'!$K$6:$K$68,$I8)="","",INDEX('TEa input'!$K$6:$K$68,$I8)) | N8: =IF(INDEX('TEa input'!$M$6:$M$68,$I8)="","",INDEX('TEa input'!$M$6:$M$68,$I8)) -> 8 | O8: =IF(INDEX('TEa input'!$O$6:$O$68,$I8)="","",INDEX('TEa input'!$O$6:$O$68,$I8)) -> 12 | P8: =IF(INDEX('TEa input'!$Q$6:$Q$68,$I8)="","",INDEX('TEa input'!$Q$6:$Q$68,$I8)) -> 15 | Q8: =IF(INDEX('TEa input'!$R$6:$R$68,$I8)="","",INDEX('TEa input'!$R$6:$R$68,$I8)) -> 10.9 | R8: =IF(INDEX('TEa input'!$T$6:$T$68,$I8)="","",INDEX('TEa input'!$T$6:$T$68,$I8)) -> 20 | S8: =IF(INDEX('TEa input'!$Y$6:$Y$68,$I8)="","",INDEX('TEa input'!$Y$6:$Y$68,$I8)) -> 3.9013021 | T8: =IF(INDEX('TEa input'!$Z$6:$Z$68,$I8)="","",INDEX('TEa input'!$Z$6:$Z$68,$I8)) -> 7.8026041 | U8: =IF(INDEX('TEa input'!$AA$6:$AA$68,$I8)="","",INDEX('TEa input'!$AA$6:$AA$68,$I8)) -> 11.703906 | V8: =IF(INDEX('TEa input'!$AB$6:$AB$68,$I8)="","",INDEX('TEa input'!$AB$6:$AB$68,$I8)) | W8: =IF(INDEX('TEa input'!$AC$6:$AC$68,$I8)="","",INDEX('TEa input'!$AC$6:$AC$68,$I8)) -> 8.87 | X8: =IF(INDEX('TEa input'!$AD$6:$AD$68,$I8)="","",INDEX('TEa input'!$AD$6:$AD$68,$I8)) | Y8: =IF(INDEX('TEa input'!$AF$6:$AF$68,$I8)="","",INDEX('TEa input'!$AF$6:$AF$68,$I8)) | AA8: =IF(OR(J8="",$E8="",N($E8)<=0),"",(J8-ABS(N($F8)))/$E8) -> 4.1429322 | AB8: =IF(OR(K8="",$E8="",N($E8)<=0),"",(K8-ABS(N($F8)))/$E8) -> 5.1939044 | AC8: =IF(OR(L8="",$E8="",N($E8)<=0),"",(L8-ABS(N($F8)))/$E8) -> 5.9821335 | AD8: =IF(OR(M8="",$E8="",N($E8)<=0),"",(M8-ABS(N($F8)))/$E8) | AE8: =IF(OR(N8="",$E8="",N($E8)<=0),"",(N8-ABS(N($F8)))/$E8) -> 4.1429322 | AF8: =IF(OR(O8="",$E8="",N($E8)<=0),"",(O8-ABS(N($F8)))/$E8) -> 6.2448765 | AG8: =IF(OR(P8="",$E8="",N($E8)<=0),"",(P8-ABS(N($F8)))/$E8) -> 7.8213347 | AH8: =IF(OR(Q8="",$E8="",N($E8)<=0),"",(Q8-ABS(N($F8)))/$E8) -> 5.6668418 | ... AP8: =IF(OR(Y8="",$E8="",N($E8)<=0),"",(Y8-ABS(N($F8)))/$E8)
A9: Creatinine | B9: L2 | C9: ClinChem 3 | D9: 356.985 | E9: 1.288 | F9: 0.073 | G9: 1303 | H9: c703-1.1 | I9: =MATCH(A9,'TEa input'!$A$6:$A$68,0) -> 2 | J9: =IF(INDEX('TEa input'!$E$6:$E$68,$I9)="","",INDEX('TEa input'!$E$6:$E$68,$I9)) -> 8 | K9: =IF(INDEX('TEa input'!$G$6:$G$68,$I9)="","",INDEX('TEa input'!$G$6:$G$68,$I9)) -> 10 | L9: =IF(INDEX('TEa input'!$I$6:$I$68,$I9)="","",INDEX('TEa input'!$I$6:$I$68,$I9)) -> 11.5 | M9: =IF(INDEX('TEa input'!$K$6:$K$68,$I9)="","",INDEX('TEa input'!$K$6:$K$68,$I9)) | N9: =IF(INDEX('TEa input'!$M$6:$M$68,$I9)="","",INDEX('TEa input'!$M$6:$M$68,$I9)) -> 8 | O9: =IF(INDEX('TEa input'!$O$6:$O$68,$I9)="","",INDEX('TEa input'!$O$6:$O$68,$I9)) -> 12 | P9: =IF(INDEX('TEa input'!$Q$6:$Q$68,$I9)="","",INDEX('TEa input'!$Q$6:$Q$68,$I9)) -> 15 | Q9: =IF(INDEX('TEa input'!$R$6:$R$68,$I9)="","",INDEX('TEa input'!$R$6:$R$68,$I9)) -> 10.9 | R9: =IF(INDEX('TEa input'!$T$6:$T$68,$I9)="","",INDEX('TEa input'!$T$6:$T$68,$I9)) -> 20 | S9: =IF(INDEX('TEa input'!$Y$6:$Y$68,$I9)="","",INDEX('TEa input'!$Y$6:$Y$68,$I9)) -> 3.9013021 | T9: =IF(INDEX('TEa input'!$Z$6:$Z$68,$I9)="","",INDEX('TEa input'!$Z$6:$Z$68,$I9)) -> 7.8026041 | U9: =IF(INDEX('TEa input'!$AA$6:$AA$68,$I9)="","",INDEX('TEa input'!$AA$6:$AA$68,$I9)) -> 11.703906 | V9: =IF(INDEX('TEa input'!$AB$6:$AB$68,$I9)="","",INDEX('TEa input'!$AB$6:$AB$68,$I9)) | W9: =IF(INDEX('TEa input'!$AC$6:$AC$68,$I9)="","",INDEX('TEa input'!$AC$6:$AC$68,$I9)) -> 8.87 | X9: =IF(INDEX('TEa input'!$AD$6:$AD$68,$I9)="","",INDEX('TEa input'!$AD$6:$AD$68,$I9)) | Y9: =IF(INDEX('TEa input'!$AF$6:$AF$68,$I9)="","",INDEX('TEa input'!$AF$6:$AF$68,$I9)) | AA9: =IF(OR(J9="",$E9="",N($E9)<=0),"",(J9-ABS(N($F9)))/$E9) -> 6.1545031 | AB9: =IF(OR(K9="",$E9="",N($E9)<=0),"",(K9-ABS(N($F9)))/$E9) -> 7.7072981 | AC9: =IF(OR(L9="",$E9="",N($E9)<=0),"",(L9-ABS(N($F9)))/$E9) -> 8.8718944 | AD9: =IF(OR(M9="",$E9="",N($E9)<=0),"",(M9-ABS(N($F9)))/$E9) | AE9: =IF(OR(N9="",$E9="",N($E9)<=0),"",(N9-ABS(N($F9)))/$E9) -> 6.1545031 | AF9: =IF(OR(O9="",$E9="",N($E9)<=0),"",(O9-ABS(N($F9)))/$E9) -> 9.2600932 | AG9: =IF(OR(P9="",$E9="",N($E9)<=0),"",(P9-ABS(N($F9)))/$E9) -> 11.589286 | AH9: =IF(OR(Q9="",$E9="",N($E9)<=0),"",(Q9-ABS(N($F9)))/$E9) -> 8.4060559 | ... AP9: =IF(OR(Y9="",$E9="",N($E9)<=0),"",(Y9-ABS(N($F9)))/$E9)
A10: ALT | B10: L1 | C10: ClinChem 2 | D10: 53.6702 | E10: 2.446 | F10: 0.935 | G10: 1180 | H10: c703-1.2 | I10: =MATCH(A10,'TEa input'!$A$6:$A$68,0) -> 3 | J10: =IF(INDEX('TEa input'!$E$6:$E$68,$I10)="","",INDEX('TEa input'!$E$6:$E$68,$I10)) -> 12 | K10: =IF(INDEX('TEa input'!$G$6:$G$68,$I10)="","",INDEX('TEa input'!$G$6:$G$68,$I10)) -> 15 | L10: =IF(INDEX('TEa input'!$I$6:$I$68,$I10)="","",INDEX('TEa input'!$I$6:$I$68,$I10)) -> 11.5 | M10: =IF(INDEX('TEa input'!$K$6:$K$68,$I10)="","",INDEX('TEa input'!$K$6:$K$68,$I10)) | N10: =IF(INDEX('TEa input'!$M$6:$M$68,$I10)="","",INDEX('TEa input'!$M$6:$M$68,$I10)) -> 12 | O10: =IF(INDEX('TEa input'!$O$6:$O$68,$I10)="","",INDEX('TEa input'!$O$6:$O$68,$I10)) -> 15 | P10: =IF(INDEX('TEa input'!$Q$6:$Q$68,$I10)="","",INDEX('TEa input'!$Q$6:$Q$68,$I10)) -> 15 | Q10: =IF(INDEX('TEa input'!$R$6:$R$68,$I10)="","",INDEX('TEa input'!$R$6:$R$68,$I10)) -> 13.3 | R10: =IF(INDEX('TEa input'!$T$6:$T$68,$I10)="","",INDEX('TEa input'!$T$6:$T$68,$I10)) -> 20 | S10: =IF(INDEX('TEa input'!$Y$6:$Y$68,$I10)="","",INDEX('TEa input'!$Y$6:$Y$68,$I10)) -> 9.1496158 | T10: =IF(INDEX('TEa input'!$Z$6:$Z$68,$I10)="","",INDEX('TEa input'!$Z$6:$Z$68,$I10)) -> 18.299232 | U10: =IF(INDEX('TEa input'!$AA$6:$AA$68,$I10)="","",INDEX('TEa input'!$AA$6:$AA$68,$I10)) -> 27.448848 | V10: =IF(INDEX('TEa input'!$AB$6:$AB$68,$I10)="","",INDEX('TEa input'!$AB$6:$AB$68,$I10)) | W10: =IF(INDEX('TEa input'!$AC$6:$AC$68,$I10)="","",INDEX('TEa input'!$AC$6:$AC$68,$I10)) -> 27.48 | X10: =IF(INDEX('TEa input'!$AD$6:$AD$68,$I10)="","",INDEX('TEa input'!$AD$6:$AD$68,$I10)) | Y10: =IF(INDEX('TEa input'!$AF$6:$AF$68,$I10)="","",INDEX('TEa input'!$AF$6:$AF$68,$I10)) | AA10: =IF(OR(J10="",$E10="",N($E10)<=0),"",(J10-ABS(N($F10)))/$E10) -> 4.5237122 | AB10: =IF(OR(K10="",$E10="",N($E10)<=0),"",(K10-ABS(N($F10)))/$E10) -> 5.7502044 | AC10: =IF(OR(L10="",$E10="",N($E10)<=0),"",(L10-ABS(N($F10)))/$E10) -> 4.3192968 | AD10: =IF(OR(M10="",$E10="",N($E10)<=0),"",(M10-ABS(N($F10)))/$E10) | AE10: =IF(OR(N10="",$E10="",N($E10)<=0),"",(N10-ABS(N($F10)))/$E10) -> 4.5237122 | AF10: =IF(OR(O10="",$E10="",N($E10)<=0),"",(O10-ABS(N($F10)))/$E10) -> 5.7502044 | AG10: =IF(OR(P10="",$E10="",N($E10)<=0),"",(P10-ABS(N($F10)))/$E10) -> 5.7502044 | AH10: =IF(OR(Q10="",$E10="",N($E10)<=0),"",(Q10-ABS(N($F10)))/$E10) -> 5.0551922 | ... AP10: =IF(OR(Y10="",$E10="",N($E10)<=0),"",(Y10-ABS(N($F10)))/$E10)
A11: ALT | B11: L2 | C11: ClinChem 3 | D11: 166.062 | E11: 2.171 | F11: 1.059 | G11: 1161 | H11: c703-1.2 | I11: =MATCH(A11,'TEa input'!$A$6:$A$68,0) -> 3 | J11: =IF(INDEX('TEa input'!$E$6:$E$68,$I11)="","",INDEX('TEa input'!$E$6:$E$68,$I11)) -> 12 | K11: =IF(INDEX('TEa input'!$G$6:$G$68,$I11)="","",INDEX('TEa input'!$G$6:$G$68,$I11)) -> 15 | L11: =IF(INDEX('TEa input'!$I$6:$I$68,$I11)="","",INDEX('TEa input'!$I$6:$I$68,$I11)) -> 11.5 | M11: =IF(INDEX('TEa input'!$K$6:$K$68,$I11)="","",INDEX('TEa input'!$K$6:$K$68,$I11)) | N11: =IF(INDEX('TEa input'!$M$6:$M$68,$I11)="","",INDEX('TEa input'!$M$6:$M$68,$I11)) -> 12 | O11: =IF(INDEX('TEa input'!$O$6:$O$68,$I11)="","",INDEX('TEa input'!$O$6:$O$68,$I11)) -> 15 | P11: =IF(INDEX('TEa input'!$Q$6:$Q$68,$I11)="","",INDEX('TEa input'!$Q$6:$Q$68,$I11)) -> 15 | Q11: =IF(INDEX('TEa input'!$R$6:$R$68,$I11)="","",INDEX('TEa input'!$R$6:$R$68,$I11)) -> 13.3 | R11: =IF(INDEX('TEa input'!$T$6:$T$68,$I11)="","",INDEX('TEa input'!$T$6:$T$68,$I11)) -> 20 | S11: =IF(INDEX('TEa input'!$Y$6:$Y$68,$I11)="","",INDEX('TEa input'!$Y$6:$Y$68,$I11)) -> 9.1496158 | T11: =IF(INDEX('TEa input'!$Z$6:$Z$68,$I11)="","",INDEX('TEa input'!$Z$6:$Z$68,$I11)) -> 18.299232 | U11: =IF(INDEX('TEa input'!$AA$6:$AA$68,$I11)="","",INDEX('TEa input'!$AA$6:$AA$68,$I11)) -> 27.448848 | V11: =IF(INDEX('TEa input'!$AB$6:$AB$68,$I11)="","",INDEX('TEa input'!$AB$6:$AB$68,$I11)) | W11: =IF(INDEX('TEa input'!$AC$6:$AC$68,$I11)="","",INDEX('TEa input'!$AC$6:$AC$68,$I11)) -> 27.48 | X11: =IF(INDEX('TEa input'!$AD$6:$AD$68,$I11)="","",INDEX('TEa input'!$AD$6:$AD$68,$I11)) | Y11: =IF(INDEX('TEa input'!$AF$6:$AF$68,$I11)="","",INDEX('TEa input'!$AF$6:$AF$68,$I11)) | AA11: =IF(OR(J11="",$E11="",N($E11)<=0),"",(J11-ABS(N($F11)))/$E11) -> 5.0396131 | AB11: =IF(OR(K11="",$E11="",N($E11)<=0),"",(K11-ABS(N($F11)))/$E11) -> 6.4214648 | AC11: =IF(OR(L11="",$E11="",N($E11)<=0),"",(L11-ABS(N($F11)))/$E11) -> 4.8093045 | AD11: =IF(OR(M11="",$E11="",N($E11)<=0),"",(M11-ABS(N($F11)))/$E11) | AE11: =IF(OR(N11="",$E11="",N($E11)<=0),"",(N11-ABS(N($F11)))/$E11) -> 5.0396131 | AF11: =IF(OR(O11="",$E11="",N($E11)<=0),"",(O11-ABS(N($F11)))/$E11) -> 6.4214648 | AG11: =IF(OR(P11="",$E11="",N($E11)<=0),"",(P11-ABS(N($F11)))/$E11) -> 6.4214648 | AH11: =IF(OR(Q11="",$E11="",N($E11)<=0),"",(Q11-ABS(N($F11)))/$E11) -> 5.6384155 | ... AP11: =IF(OR(Y11="",$E11="",N($E11)<=0),"",(Y11-ABS(N($F11)))/$E11)
A12: Glucose | B12: L1 | C12: ClinChem 2 | D12: 5.30429 | E12: 1.932 | F12: 0.478 | G12: 882 | H12: c703-2.1 | I12: =MATCH(A12,'TEa input'!$A$6:$A$68,0) -> 4 | J12: =IF(INDEX('TEa input'!$E$6:$E$68,$I12)="","",INDEX('TEa input'!$E$6:$E$68,$I12)) -> 6 | K12: =IF(INDEX('TEa input'!$G$6:$G$68,$I12)="","",INDEX('TEa input'!$G$6:$G$68,$I12)) -> 8 | L12: =IF(INDEX('TEa input'!$I$6:$I$68,$I12)="","",INDEX('TEa input'!$I$6:$I$68,$I12)) -> 5 | M12: =IF(INDEX('TEa input'!$K$6:$K$68,$I12)="","",INDEX('TEa input'!$K$6:$K$68,$I12)) | N12: =IF(INDEX('TEa input'!$M$6:$M$68,$I12)="","",INDEX('TEa input'!$M$6:$M$68,$I12)) -> 8 | O12: =IF(INDEX('TEa input'!$O$6:$O$68,$I12)="","",INDEX('TEa input'!$O$6:$O$68,$I12)) -> 7 | P12: =IF(INDEX('TEa input'!$Q$6:$Q$68,$I12)="","",INDEX('TEa input'!$Q$6:$Q$68,$I12)) -> 9 | Q12: =IF(INDEX('TEa input'!$R$6:$R$68,$I12)="","",INDEX('TEa input'!$R$6:$R$68,$I12)) -> 6.3 | R12: =IF(INDEX('TEa input'!$T$6:$T$68,$I12)="","",INDEX('TEa input'!$T$6:$T$68,$I12)) -> 10 | S12: =IF(INDEX('TEa input'!$Y$6:$Y$68,$I12)="","",INDEX('TEa input'!$Y$6:$Y$68,$I12)) -> 3.204598 | T12: =IF(INDEX('TEa input'!$Z$6:$Z$68,$I12)="","",INDEX('TEa input'!$Z$6:$Z$68,$I12)) -> 6.409196 | U12: =IF(INDEX('TEa input'!$AA$6:$AA$68,$I12)="","",INDEX('TEa input'!$AA$6:$AA$68,$I12)) -> 9.613794 | V12: =IF(INDEX('TEa input'!$AB$6:$AB$68,$I12)="","",INDEX('TEa input'!$AB$6:$AB$68,$I12)) | W12: =IF(INDEX('TEa input'!$AC$6:$AC$68,$I12)="","",INDEX('TEa input'!$AC$6:$AC$68,$I12)) -> 6.96 | X12: =IF(INDEX('TEa input'!$AD$6:$AD$68,$I12)="","",INDEX('TEa input'!$AD$6:$AD$68,$I12)) | Y12: =IF(INDEX('TEa input'!$AF$6:$AF$68,$I12)="","",INDEX('TEa input'!$AF$6:$AF$68,$I12)) | AA12: =IF(OR(J12="",$E12="",N($E12)<=0),"",(J12-ABS(N($F12)))/$E12) -> 2.8581781 | AB12: =IF(OR(K12="",$E12="",N($E12)<=0),"",(K12-ABS(N($F12)))/$E12) -> 3.8933747 | AC12: =IF(OR(L12="",$E12="",N($E12)<=0),"",(L12-ABS(N($F12)))/$E12) -> 2.3405797 | AD12: =IF(OR(M12="",$E12="",N($E12)<=0),"",(M12-ABS(N($F12)))/$E12) | AE12: =IF(OR(N12="",$E12="",N($E12)<=0),"",(N12-ABS(N($F12)))/$E12) -> 3.8933747 | AF12: =IF(OR(O12="",$E12="",N($E12)<=0),"",(O12-ABS(N($F12)))/$E12) -> 3.3757764 | AG12: =IF(OR(P12="",$E12="",N($E12)<=0),"",(P12-ABS(N($F12)))/$E12) -> 4.4109731 | AH12: =IF(OR(Q12="",$E12="",N($E12)<=0),"",(Q12-ABS(N($F12)))/$E12) -> 3.0134576 | ... AP12: =IF(OR(Y12="",$E12="",N($E12)<=0),"",(Y12-ABS(N($F12)))/$E12)
A13: Glucose | B13: L2 | C13: ClinChem 3 | D13: 14.679 | E13: 1.495 | F13: 0.322 | G13: 881 | H13: c703-1.1 | I13: =MATCH(A13,'TEa input'!$A$6:$A$68,0) -> 4 | J13: =IF(INDEX('TEa input'!$E$6:$E$68,$I13)="","",INDEX('TEa input'!$E$6:$E$68,$I13)) -> 6 | K13: =IF(INDEX('TEa input'!$G$6:$G$68,$I13)="","",INDEX('TEa input'!$G$6:$G$68,$I13)) -> 8 | L13: =IF(INDEX('TEa input'!$I$6:$I$68,$I13)="","",INDEX('TEa input'!$I$6:$I$68,$I13)) -> 5 | M13: =IF(INDEX('TEa input'!$K$6:$K$68,$I13)="","",INDEX('TEa input'!$K$6:$K$68,$I13)) | N13: =IF(INDEX('TEa input'!$M$6:$M$68,$I13)="","",INDEX('TEa input'!$M$6:$M$68,$I13)) -> 8 | O13: =IF(INDEX('TEa input'!$O$6:$O$68,$I13)="","",INDEX('TEa input'!$O$6:$O$68,$I13)) -> 7 | P13: =IF(INDEX('TEa input'!$Q$6:$Q$68,$I13)="","",INDEX('TEa input'!$Q$6:$Q$68,$I13)) -> 9 | Q13: =IF(INDEX('TEa input'!$R$6:$R$68,$I13)="","",INDEX('TEa input'!$R$6:$R$68,$I13)) -> 6.3 | R13: =IF(INDEX('TEa input'!$T$6:$T$68,$I13)="","",INDEX('TEa input'!$T$6:$T$68,$I13)) -> 10 | S13: =IF(INDEX('TEa input'!$Y$6:$Y$68,$I13)="","",INDEX('TEa input'!$Y$6:$Y$68,$I13)) -> 3.204598 | T13: =IF(INDEX('TEa input'!$Z$6:$Z$68,$I13)="","",INDEX('TEa input'!$Z$6:$Z$68,$I13)) -> 6.409196 | U13: =IF(INDEX('TEa input'!$AA$6:$AA$68,$I13)="","",INDEX('TEa input'!$AA$6:$AA$68,$I13)) -> 9.613794 | V13: =IF(INDEX('TEa input'!$AB$6:$AB$68,$I13)="","",INDEX('TEa input'!$AB$6:$AB$68,$I13)) | W13: =IF(INDEX('TEa input'!$AC$6:$AC$68,$I13)="","",INDEX('TEa input'!$AC$6:$AC$68,$I13)) -> 6.96 | X13: =IF(INDEX('TEa input'!$AD$6:$AD$68,$I13)="","",INDEX('TEa input'!$AD$6:$AD$68,$I13)) | Y13: =IF(INDEX('TEa input'!$AF$6:$AF$68,$I13)="","",INDEX('TEa input'!$AF$6:$AF$68,$I13)) | AA13: =IF(OR(J13="",$E13="",N($E13)<=0),"",(J13-ABS(N($F13)))/$E13) -> 3.7979933 | AB13: =IF(OR(K13="",$E13="",N($E13)<=0),"",(K13-ABS(N($F13)))/$E13) -> 5.135786 | AC13: =IF(OR(L13="",$E13="",N($E13)<=0),"",(L13-ABS(N($F13)))/$E13) -> 3.129097 | AD13: =IF(OR(M13="",$E13="",N($E13)<=0),"",(M13-ABS(N($F13)))/$E13) | AE13: =IF(OR(N13="",$E13="",N($E13)<=0),"",(N13-ABS(N($F13)))/$E13) -> 5.135786 | AF13: =IF(OR(O13="",$E13="",N($E13)<=0),"",(O13-ABS(N($F13)))/$E13) -> 4.4668896 | AG13: =IF(OR(P13="",$E13="",N($E13)<=0),"",(P13-ABS(N($F13)))/$E13) -> 5.8046823 | AH13: =IF(OR(Q13="",$E13="",N($E13)<=0),"",(Q13-ABS(N($F13)))/$E13) -> 3.9986622 | ... AP13: =IF(OR(Y13="",$E13="",N($E13)<=0),"",(Y13-ABS(N($F13)))/$E13)
A14: Calcium | B14: L1 | C14: ClinChem 2 | D14: 2.24434 | E14: 1.19 | F14: 0.67 | G14: 897 | H14: c703-1.1 | I14: =MATCH(A14,'TEa input'!$A$6:$A$68,0) -> 5 | J14: =IF(INDEX('TEa input'!$E$6:$E$68,$I14)="","",INDEX('TEa input'!$E$6:$E$68,$I14)) -> 3 | K14: =IF(INDEX('TEa input'!$G$6:$G$68,$I14)="","",INDEX('TEa input'!$G$6:$G$68,$I14)) | L14: =IF(INDEX('TEa input'!$I$6:$I$68,$I14)="","",INDEX('TEa input'!$I$6:$I$68,$I14)) -> 6 | M14: =IF(INDEX('TEa input'!$K$6:$K$68,$I14)="","",INDEX('TEa input'!$K$6:$K$68,$I14)) | N14: =IF(INDEX('TEa input'!$M$6:$M$68,$I14)="","",INDEX('TEa input'!$M$6:$M$68,$I14)) -> 4 | O14: =IF(INDEX('TEa input'!$O$6:$O$68,$I14)="","",INDEX('TEa input'!$O$6:$O$68,$I14)) -> 5 | P14: =IF(INDEX('TEa input'!$Q$6:$Q$68,$I14)="","",INDEX('TEa input'!$Q$6:$Q$68,$I14)) -> 10 | Q14: =IF(INDEX('TEa input'!$R$6:$R$68,$I14)="","",INDEX('TEa input'!$R$6:$R$68,$I14)) -> 5 | R14: =IF(INDEX('TEa input'!$T$6:$T$68,$I14)="","",INDEX('TEa input'!$T$6:$T$68,$I14)) -> 10 | S14: =IF(INDEX('TEa input'!$Y$6:$Y$68,$I14)="","",INDEX('TEa input'!$Y$6:$Y$68,$I14)) -> 1.1481245 | T14: =IF(INDEX('TEa input'!$Z$6:$Z$68,$I14)="","",INDEX('TEa input'!$Z$6:$Z$68,$I14)) -> 2.296249 | U14: =IF(INDEX('TEa input'!$AA$6:$AA$68,$I14)="","",INDEX('TEa input'!$AA$6:$AA$68,$I14)) -> 3.4443736 | V14: =IF(INDEX('TEa input'!$AB$6:$AB$68,$I14)="","",INDEX('TEa input'!$AB$6:$AB$68,$I14)) | W14: =IF(INDEX('TEa input'!$AC$6:$AC$68,$I14)="","",INDEX('TEa input'!$AC$6:$AC$68,$I14)) -> 2.55 | X14: =IF(INDEX('TEa input'!$AD$6:$AD$68,$I14)="","",INDEX('TEa input'!$AD$6:$AD$68,$I14)) | Y14: =IF(INDEX('TEa input'!$AF$6:$AF$68,$I14)="","",INDEX('TEa input'!$AF$6:$AF$68,$I14)) | AA14: =IF(OR(J14="",$E14="",N($E14)<=0),"",(J14-ABS(N($F14)))/$E14) -> 1.9579832 | AB14: =IF(OR(K14="",$E14="",N($E14)<=0),"",(K14-ABS(N($F14)))/$E14) | AC14: =IF(OR(L14="",$E14="",N($E14)<=0),"",(L14-ABS(N($F14)))/$E14) -> 4.4789916 | AD14: =IF(OR(M14="",$E14="",N($E14)<=0),"",(M14-ABS(N($F14)))/$E14) | AE14: =IF(OR(N14="",$E14="",N($E14)<=0),"",(N14-ABS(N($F14)))/$E14) -> 2.7983193 | AF14: =IF(OR(O14="",$E14="",N($E14)<=0),"",(O14-ABS(N($F14)))/$E14) -> 3.6386555 | AG14: =IF(OR(P14="",$E14="",N($E14)<=0),"",(P14-ABS(N($F14)))/$E14) -> 7.8403361 | AH14: =IF(OR(Q14="",$E14="",N($E14)<=0),"",(Q14-ABS(N($F14)))/$E14) -> 3.6386555 | ... AP14: =IF(OR(Y14="",$E14="",N($E14)<=0),"",(Y14-ABS(N($F14)))/$E14)
A15: Calcium | B15: L2 | C15: ClinChem 3 | D15: 3.13051 | E15: 0.998 | F15: 0.476 | G15: 889 | H15: c703-1.1 | I15: =MATCH(A15,'TEa input'!$A$6:$A$68,0) -> 5 | J15: =IF(INDEX('TEa input'!$E$6:$E$68,$I15)="","",INDEX('TEa input'!$E$6:$E$68,$I15)) -> 3 | K15: =IF(INDEX('TEa input'!$G$6:$G$68,$I15)="","",INDEX('TEa input'!$G$6:$G$68,$I15)) | L15: =IF(INDEX('TEa input'!$I$6:$I$68,$I15)="","",INDEX('TEa input'!$I$6:$I$68,$I15)) -> 6 | M15: =IF(INDEX('TEa input'!$K$6:$K$68,$I15)="","",INDEX('TEa input'!$K$6:$K$68,$I15)) | N15: =IF(INDEX('TEa input'!$M$6:$M$68,$I15)="","",INDEX('TEa input'!$M$6:$M$68,$I15)) -> 4 | O15: =IF(INDEX('TEa input'!$O$6:$O$68,$I15)="","",INDEX('TEa input'!$O$6:$O$68,$I15)) -> 5 | P15: =IF(INDEX('TEa input'!$Q$6:$Q$68,$I15)="","",INDEX('TEa input'!$Q$6:$Q$68,$I15)) -> 10 | Q15: =IF(INDEX('TEa input'!$R$6:$R$68,$I15)="","",INDEX('TEa input'!$R$6:$R$68,$I15)) -> 5 | R15: =IF(INDEX('TEa input'!$T$6:$T$68,$I15)="","",INDEX('TEa input'!$T$6:$T$68,$I15)) -> 10 | S15: =IF(INDEX('TEa input'!$Y$6:$Y$68,$I15)="","",INDEX('TEa input'!$Y$6:$Y$68,$I15)) -> 1.1481245 | T15: =IF(INDEX('TEa input'!$Z$6:$Z$68,$I15)="","",INDEX('TEa input'!$Z$6:$Z$68,$I15)) -> 2.296249 | U15: =IF(INDEX('TEa input'!$AA$6:$AA$68,$I15)="","",INDEX('TEa input'!$AA$6:$AA$68,$I15)) -> 3.4443736 | V15: =IF(INDEX('TEa input'!$AB$6:$AB$68,$I15)="","",INDEX('TEa input'!$AB$6:$AB$68,$I15)) | W15: =IF(INDEX('TEa input'!$AC$6:$AC$68,$I15)="","",INDEX('TEa input'!$AC$6:$AC$68,$I15)) -> 2.55 | X15: =IF(INDEX('TEa input'!$AD$6:$AD$68,$I15)="","",INDEX('TEa input'!$AD$6:$AD$68,$I15)) | Y15: =IF(INDEX('TEa input'!$AF$6:$AF$68,$I15)="","",INDEX('TEa input'!$AF$6:$AF$68,$I15)) | AA15: =IF(OR(J15="",$E15="",N($E15)<=0),"",(J15-ABS(N($F15)))/$E15) -> 2.5290581 | AB15: =IF(OR(K15="",$E15="",N($E15)<=0),"",(K15-ABS(N($F15)))/$E15) | AC15: =IF(OR(L15="",$E15="",N($E15)<=0),"",(L15-ABS(N($F15)))/$E15) -> 5.5350701 | AD15: =IF(OR(M15="",$E15="",N($E15)<=0),"",(M15-ABS(N($F15)))/$E15) | AE15: =IF(OR(N15="",$E15="",N($E15)<=0),"",(N15-ABS(N($F15)))/$E15) -> 3.5310621 | AF15: =IF(OR(O15="",$E15="",N($E15)<=0),"",(O15-ABS(N($F15)))/$E15) -> 4.5330661 | AG15: =IF(OR(P15="",$E15="",N($E15)<=0),"",(P15-ABS(N($F15)))/$E15) -> 9.5430862 | AH15: =IF(OR(Q15="",$E15="",N($E15)<=0),"",(Q15-ABS(N($F15)))/$E15) -> 4.5330661 | ... AP15: =IF(OR(Y15="",$E15="",N($E15)<=0),"",(Y15-ABS(N($F15)))/$E15)
A16: TSH | B16: L1 | C16: IMMUN L1 | D16: 3.02944 | E16: 2.462 | F16: 0.894 | G16: 1866 | H16: e801-2.1 | I16: =MATCH(A16,'TEa input'!$A$6:$A$68,0) -> 6 | J16: =IF(INDEX('TEa input'!$E$6:$E$68,$I16)="","",INDEX('TEa input'!$E$6:$E$68,$I16)) | K16: =IF(INDEX('TEa input'!$G$6:$G$68,$I16)="","",INDEX('TEa input'!$G$6:$G$68,$I16)) -> 20 | L16: =IF(INDEX('TEa input'!$I$6:$I$68,$I16)="","",INDEX('TEa input'!$I$6:$I$68,$I16)) -> 13.5 | M16: =IF(INDEX('TEa input'!$K$6:$K$68,$I16)="","",INDEX('TEa input'!$K$6:$K$68,$I16)) | N16: =IF(INDEX('TEa input'!$M$6:$M$68,$I16)="","",INDEX('TEa input'!$M$6:$M$68,$I16)) -> 20 | O16: =IF(INDEX('TEa input'!$O$6:$O$68,$I16)="","",INDEX('TEa input'!$O$6:$O$68,$I16)) -> 20 | P16: =IF(INDEX('TEa input'!$Q$6:$Q$68,$I16)="","",INDEX('TEa input'!$Q$6:$Q$68,$I16)) -> 14 | Q16: =IF(INDEX('TEa input'!$R$6:$R$68,$I16)="","",INDEX('TEa input'!$R$6:$R$68,$I16)) | R16: =IF(INDEX('TEa input'!$T$6:$T$68,$I16)="","",INDEX('TEa input'!$T$6:$T$68,$I16)) -> 25 | S16: =IF(INDEX('TEa input'!$Y$6:$Y$68,$I16)="","",INDEX('TEa input'!$Y$6:$Y$68,$I16)) -> 12.420521 | T16: =IF(INDEX('TEa input'!$Z$6:$Z$68,$I16)="","",INDEX('TEa input'!$Z$6:$Z$68,$I16)) -> 24.841042 | U16: =IF(INDEX('TEa input'!$AA$6:$AA$68,$I16)="","",INDEX('TEa input'!$AA$6:$AA$68,$I16)) -> 37.261563 | V16: =IF(INDEX('TEa input'!$AB$6:$AB$68,$I16)="","",INDEX('TEa input'!$AB$6:$AB$68,$I16)) | W16: =IF(INDEX('TEa input'!$AC$6:$AC$68,$I16)="","",INDEX('TEa input'!$AC$6:$AC$68,$I16)) -> 23.7 | X16: =IF(INDEX('TEa input'!$AD$6:$AD$68,$I16)="","",INDEX('TEa input'!$AD$6:$AD$68,$I16)) | Y16: =IF(INDEX('TEa input'!$AF$6:$AF$68,$I16)="","",INDEX('TEa input'!$AF$6:$AF$68,$I16)) | AA16: =IF(OR(J16="",$E16="",N($E16)<=0),"",(J16-ABS(N($F16)))/$E16) | AB16: =IF(OR(K16="",$E16="",N($E16)<=0),"",(K16-ABS(N($F16)))/$E16) -> 7.7603574 | AC16: =IF(OR(L16="",$E16="",N($E16)<=0),"",(L16-ABS(N($F16)))/$E16) -> 5.1202275 | AD16: =IF(OR(M16="",$E16="",N($E16)<=0),"",(M16-ABS(N($F16)))/$E16) | AE16: =IF(OR(N16="",$E16="",N($E16)<=0),"",(N16-ABS(N($F16)))/$E16) -> 7.7603574 | AF16: =IF(OR(O16="",$E16="",N($E16)<=0),"",(O16-ABS(N($F16)))/$E16) -> 7.7603574 | AG16: =IF(OR(P16="",$E16="",N($E16)<=0),"",(P16-ABS(N($F16)))/$E16) -> 5.3233144 | AH16: =IF(OR(Q16="",$E16="",N($E16)<=0),"",(Q16-ABS(N($F16)))/$E16) | ... AP16: =IF(OR(Y16="",$E16="",N($E16)<=0),"",(Y16-ABS(N($F16)))/$E16)
A17: TSH | B17: L2 | C17: IMMUN L2 | D17: 10.4928 | E17: 2.287 | F17: 0.874 | G17: 1856 | H17: e801-1.1 | I17: =MATCH(A17,'TEa input'!$A$6:$A$68,0) -> 6 | J17: =IF(INDEX('TEa input'!$E$6:$E$68,$I17)="","",INDEX('TEa input'!$E$6:$E$68,$I17)) | K17: =IF(INDEX('TEa input'!$G$6:$G$68,$I17)="","",INDEX('TEa input'!$G$6:$G$68,$I17)) -> 20 | L17: =IF(INDEX('TEa input'!$I$6:$I$68,$I17)="","",INDEX('TEa input'!$I$6:$I$68,$I17)) -> 13.5 | M17: =IF(INDEX('TEa input'!$K$6:$K$68,$I17)="","",INDEX('TEa input'!$K$6:$K$68,$I17)) | N17: =IF(INDEX('TEa input'!$M$6:$M$68,$I17)="","",INDEX('TEa input'!$M$6:$M$68,$I17)) -> 20 | O17: =IF(INDEX('TEa input'!$O$6:$O$68,$I17)="","",INDEX('TEa input'!$O$6:$O$68,$I17)) -> 20 | P17: =IF(INDEX('TEa input'!$Q$6:$Q$68,$I17)="","",INDEX('TEa input'!$Q$6:$Q$68,$I17)) -> 14 | Q17: =IF(INDEX('TEa input'!$R$6:$R$68,$I17)="","",INDEX('TEa input'!$R$6:$R$68,$I17)) | R17: =IF(INDEX('TEa input'!$T$6:$T$68,$I17)="","",INDEX('TEa input'!$T$6:$T$68,$I17)) -> 25 | S17: =IF(INDEX('TEa input'!$Y$6:$Y$68,$I17)="","",INDEX('TEa input'!$Y$6:$Y$68,$I17)) -> 12.420521 | T17: =IF(INDEX('TEa input'!$Z$6:$Z$68,$I17)="","",INDEX('TEa input'!$Z$6:$Z$68,$I17)) -> 24.841042 | U17: =IF(INDEX('TEa input'!$AA$6:$AA$68,$I17)="","",INDEX('TEa input'!$AA$6:$AA$68,$I17)) -> 37.261563 | V17: =IF(INDEX('TEa input'!$AB$6:$AB$68,$I17)="","",INDEX('TEa input'!$AB$6:$AB$68,$I17)) | W17: =IF(INDEX('TEa input'!$AC$6:$AC$68,$I17)="","",INDEX('TEa input'!$AC$6:$AC$68,$I17)) -> 23.7 | X17: =IF(INDEX('TEa input'!$AD$6:$AD$68,$I17)="","",INDEX('TEa input'!$AD$6:$AD$68,$I17)) | Y17: =IF(INDEX('TEa input'!$AF$6:$AF$68,$I17)="","",INDEX('TEa input'!$AF$6:$AF$68,$I17)) | AA17: =IF(OR(J17="",$E17="",N($E17)<=0),"",(J17-ABS(N($F17)))/$E17) | AB17: =IF(OR(K17="",$E17="",N($E17)<=0),"",(K17-ABS(N($F17)))/$E17) -> 8.3629209 | AC17: =IF(OR(L17="",$E17="",N($E17)<=0),"",(L17-ABS(N($F17)))/$E17) -> 5.5207696 | AD17: =IF(OR(M17="",$E17="",N($E17)<=0),"",(M17-ABS(N($F17)))/$E17) | AE17: =IF(OR(N17="",$E17="",N($E17)<=0),"",(N17-ABS(N($F17)))/$E17) -> 8.3629209 | AF17: =IF(OR(O17="",$E17="",N($E17)<=0),"",(O17-ABS(N($F17)))/$E17) -> 8.3629209 | AG17: =IF(OR(P17="",$E17="",N($E17)<=0),"",(P17-ABS(N($F17)))/$E17) -> 5.7393966 | AH17: =IF(OR(Q17="",$E17="",N($E17)<=0),"",(Q17-ABS(N($F17)))/$E17) | ... AP17: =IF(OR(Y17="",$E17="",N($E17)<=0),"",(Y17-ABS(N($F17)))/$E17)
... A138: Digoxin | B138: L2 | C138: IMMUN L2 | D138: 2.67603 | E138: 3.856 | F138: 1.084 | G138: 1050 | H138: e801-1.1 | I138: =MATCH(A138,'TEa input'!$A$6:$A$68,0) -> 63 | J138: =IF(INDEX('TEa input'!$E$6:$E$68,$I138)="","",INDEX('TEa input'!$E$6:$E$68,$I138)) | K138: =IF(INDEX('TEa input'!$G$6:$G$68,$I138)="","",INDEX('TEa input'!$G$6:$G$68,$I138)) -> 15 | L138: =IF(INDEX('TEa input'!$I$6:$I$68,$I138)="","",INDEX('TEa input'!$I$6:$I$68,$I138)) | M138: =IF(INDEX('TEa input'!$K$6:$K$68,$I138)="","",INDEX('TEa input'!$K$6:$K$68,$I138)) | N138: =IF(INDEX('TEa input'!$M$6:$M$68,$I138)="","",INDEX('TEa input'!$M$6:$M$68,$I138)) -> 10 | O138: =IF(INDEX('TEa input'!$O$6:$O$68,$I138)="","",INDEX('TEa input'!$O$6:$O$68,$I138)) | P138: =IF(INDEX('TEa input'!$Q$6:$Q$68,$I138)="","",INDEX('TEa input'!$Q$6:$Q$68,$I138)) -> 30 | Q138: =IF(INDEX('TEa input'!$R$6:$R$68,$I138)="","",INDEX('TEa input'!$R$6:$R$68,$I138)) | R138: =IF(INDEX('TEa input'!$T$6:$T$68,$I138)="","",INDEX('TEa input'!$T$6:$T$68,$I138)) | S138: =IF(INDEX('TEa input'!$Y$6:$Y$68,$I138)="","",INDEX('TEa input'!$Y$6:$Y$68,$I138)) | T138: =IF(INDEX('TEa input'!$Z$6:$Z$68,$I138)="","",INDEX('TEa input'!$Z$6:$Z$68,$I138)) | U138: =IF(INDEX('TEa input'!$AA$6:$AA$68,$I138)="","",INDEX('TEa input'!$AA$6:$AA$68,$I138)) | V138: =IF(INDEX('TEa input'!$AB$6:$AB$68,$I138)="","",INDEX('TEa input'!$AB$6:$AB$68,$I138)) | W138: =IF(INDEX('TEa input'!$AC$6:$AC$68,$I138)="","",INDEX('TEa input'!$AC$6:$AC$68,$I138)) | X138: =IF(INDEX('TEa input'!$AD$6:$AD$68,$I138)="","",INDEX('TEa input'!$AD$6:$AD$68,$I138)) | Y138: =IF(INDEX('TEa input'!$AF$6:$AF$68,$I138)="","",INDEX('TEa input'!$AF$6:$AF$68,$I138)) | AA138: =IF(OR(J138="",$E138="",N($E138)<=0),"",(J138-ABS(N($F138)))/$E138) | AB138: =IF(OR(K138="",$E138="",N($E138)<=0),"",(K138-ABS(N($F138)))/$E138) -> 3.6089212 | AC138: =IF(OR(L138="",$E138="",N($E138)<=0),"",(L138-ABS(N($F138)))/$E138) | AD138: =IF(OR(M138="",$E138="",N($E138)<=0),"",(M138-ABS(N($F138)))/$E138) | AE138: =IF(OR(N138="",$E138="",N($E138)<=0),"",(N138-ABS(N($F138)))/$E138) -> 2.3122407 | AF138: =IF(OR(O138="",$E138="",N($E138)<=0),"",(O138-ABS(N($F138)))/$E138) | AG138: =IF(OR(P138="",$E138="",N($E138)<=0),"",(P138-ABS(N($F138)))/$E138) -> 7.4989627 | AH138: =IF(OR(Q138="",$E138="",N($E138)<=0),"",(Q138-ABS(N($F138)))/$E138) | ... AP138: =IF(OR(Y138="",$E138="",N($E138)<=0),"",(Y138-ABS(N($F138)))/$E138)

Sheet For the tool
A1: TEa to enter in the tool — analyte × source
A2: One TEa % per analyte and source. 'Lowest sigma' is the weakest control level for that source; filter to hide empty sources.
A4: Analyte | B4: Group | C4: Source (name in the tool) | D4: TEa % | E4: Lowest sigma across levels
A5: Sodium | B5: Panel | C5: Labquality | D5: =IF('TEa input'!E6="","",'TEa input'!E6) -> 2 | E5: =IF(D5="","",MIN(Sigma!AA6:AA7)) -> 1.6213235
A6: Sodium | B6: Panel | C6: CLIA | D6: =IF('TEa input'!G6="","",'TEa input'!G6) | E6: =IF(D6="","",MIN(Sigma!AB6:AB7))
A7: Sodium | B7: Panel | C7: Rili-BÄK | D7: =IF('TEa input'!I6="","",'TEa input'!I6) -> 3 | E7: =IF(D7="","",MIN(Sigma!AC6:AC7)) -> 2.5404412
A8: Sodium | B8: Panel | C8: Noklus | D8: =IF('TEa input'!K6="","",'TEa input'!K6) | E8: =IF(D8="","",MIN(Sigma!AD6:AD7))
A9: Sodium | B9: Panel | C9: RCPA | D9: =IF('TEa input'!M6="","",'TEa input'!M6) -> 2 | E9: =IF(D9="","",MIN(Sigma!AE6:AE7)) -> 1.6213235
A10: Sodium | B10: Panel | C10: China WS/T 403-2024 | D10: =IF('TEa input'!O6="","",'TEa input'!O6) -> 4 | E10: =IF(D10="","",MIN(Sigma!AF6:AF7)) -> 3.4595588
A11: Sodium | B11: Panel | C11: SEKK Dmax | D11: =IF('TEa input'!Q6="","",'TEa input'!Q6) -> 5 | E11: =IF(D11="","",MIN(Sigma!AG6:AG7)) -> 4.3786765
A12: Sodium | B12: Panel | C12: Belgium WIV-ISP | D12: =IF('TEa input'!R6="","",'TEa input'!R6) -> 3.4 | E12: =IF(D12="","",MIN(Sigma!AH6:AH7)) -> 2.9080882
A13: Sodium | B13: Panel | C13: Turkey MoH 2026 | D13: =IF('TEa input'!T6="","",'TEa input'!T6) -> 9 | E13: =IF(D13="","",MIN(Sigma!AI6:AI7)) -> 8.0551471
A14: Sodium | B14: Panel | C14: BV EFLM (optimal) | D14: =IF('TEa input'!Y6="","",'TEa input'!Y6) -> 0.31377907 | E14: =IF(D14="","",MIN(Sigma!AJ6:AJ7)) -> 0.071488112
A15: Sodium | B15: Panel | C15: BV EFLM (desirable) | D15: =IF('TEa input'!Z6="","",'TEa input'!Z6) -> 0.62755813 | E15: =IF(D15="","",MIN(Sigma!AK6:AK7)) -> 0.35988799
A16: Sodium | B16: Panel | C16: BV EFLM (minimum) | D16: =IF('TEa input'!AA6="","",'TEa input'!AA6) -> 0.9413372 | E16: =IF(D16="","",MIN(Sigma!AL6:AL7)) -> 0.64828787
A17: Sodium | B17: Panel | C17: BV Ricos (optimal) | D17: =IF('TEa input'!AB6="","",'TEa input'!AB6) | E17: =IF(D17="","",MIN(Sigma!AM6:AM7))
A18: Sodium | B18: Panel | C18: BV Ricos (desirable) | D18: =IF('TEa input'!AC6="","",'TEa input'!AC6) -> 0.73 | E18: =IF(D18="","",MIN(Sigma!AN6:AN7)) -> 0.45404412
A19: Sodium | B19: Panel | C19: BV Ricos (minimum) | D19: =IF('TEa input'!AD6="","",'TEa input'!AD6) | E19: =IF(D19="","",MIN(Sigma!AO6:AO7))
A20: Sodium | B20: Panel | C20: =IF('TEa input'!AE6="","Other",'TEa input'!AE6) -> Other | D20: =IF('TEa input'!AF6="","",'TEa input'!AF6) | E20: =IF(D20="","",MIN(Sigma!AP6:AP7))
A21: Creatinine | B21: Panel | C21: Labquality | D21: =IF('TEa input'!E7="","",'TEa input'!E7) -> 8 | E21: =IF(D21="","",MIN(Sigma!AA8:AA9)) -> 4.1429322
A22: Creatinine | B22: Panel | C22: CLIA | D22: =IF('TEa input'!G7="","",'TEa input'!G7) -> 10 | E22: =IF(D22="","",MIN(Sigma!AB8:AB9)) -> 5.1939044
A23: Creatinine | B23: Panel | C23: Rili-BÄK | D23: =IF('TEa input'!I7="","",'TEa input'!I7) -> 11.5 | E23: =IF(D23="","",MIN(Sigma!AC8:AC9)) -> 5.9821335
A24: Creatinine | B24: Panel | C24: Noklus | D24: =IF('TEa input'!K7="","",'TEa input'!K7) | E24: =IF(D24="","",MIN(Sigma!AD8:AD9))
A25: Creatinine | B25: Panel | C25: RCPA | D25: =IF('TEa input'!M7="","",'TEa input'!M7) -> 8 | E25: =IF(D25="","",MIN(Sigma!AE8:AE9)) -> 4.1429322
A26: Creatinine | B26: Panel | C26: China WS/T 403-2024 | D26: =IF('TEa input'!O7="","",'TEa input'!O7) -> 12 | E26: =IF(D26="","",MIN(Sigma!AF8:AF9)) -> 6.2448765
A27: Creatinine | B27: Panel | C27: SEKK Dmax | D27: =IF('TEa input'!Q7="","",'TEa input'!Q7) -> 15 | E27: =IF(D27="","",MIN(Sigma!AG8:AG9)) -> 7.8213347
A28: Creatinine | B28: Panel | C28: Belgium WIV-ISP | D28: =IF('TEa input'!R7="","",'TEa input'!R7) -> 10.9 | E28: =IF(D28="","",MIN(Sigma!AH8:AH9)) -> 5.6668418
A29: Creatinine | B29: Panel | C29: Turkey MoH 2026 | D29: =IF('TEa input'!T7="","",'TEa input'!T7) -> 20 | E29: =IF(D29="","",MIN(Sigma!AI8:AI9)) -> 10.448765
A30: Creatinine | B30: Panel | C30: BV EFLM (optimal) | D30: =IF('TEa input'!Y7="","",'TEa input'!Y7) -> 3.9013021 | E30: =IF(D30="","",MIN(Sigma!AJ8:AJ9)) -> 1.9891235
A31: Creatinine | B31: Panel | C31: BV EFLM (desirable) | D31: =IF('TEa input'!Z7="","",'TEa input'!Z7) -> 7.8026041 | E31: =IF(D31="","",MIN(Sigma!AK8:AK9)) -> 4.0392034
A32: Creatinine | B32: Panel | C32: BV EFLM (minimum) | D32: =IF('TEa input'!AA7="","",'TEa input'!AA7) -> 11.703906 | E32: =IF(D32="","",MIN(Sigma!AL8:AL9)) -> 6.0892833
A33: Creatinine | B33: Panel | C33: BV Ricos (optimal) | D33: =IF('TEa input'!AB7="","",'TEa input'!AB7) | E33: =IF(D33="","",MIN(Sigma!AM8:AM9))
A34: Creatinine | B34: Panel | C34: BV Ricos (desirable) | D34: =IF('TEa input'!AC7="","",'TEa input'!AC7) -> 8.87 | E34: =IF(D34="","",MIN(Sigma!AN8:AN9)) -> 4.6001051
A35: Creatinine | B35: Panel | C35: BV Ricos (minimum) | D35: =IF('TEa input'!AD7="","",'TEa input'!AD7) | E35: =IF(D35="","",MIN(Sigma!AO8:AO9))
